looking for food in files/74OL[2018-12-03 16:11:50,020] ERROR in app: Exception on /upload [POST]
Traceback (most recent call last):
  File "/home/ubuntu/.local/lib/python2.7/site-packages/flask/app.py", line 2292, in wsgi_app
    response = self.full_dispatch_request()
  File "/home/ubuntu/.local/lib/python2.7/site-packages/flask/app.py", line 1815, in full_dispatch_request
    rv = self.handle_user_exception(e)
  File "/home/ubuntu/.local/lib/python2.7/site-packages/flask/app.py", line 1718, in handle_user_exception
    reraise(exc_type, exc_value, tb)
  File "/home/ubuntu/.local/lib/python2.7/site-packages/flask/app.py", line 1813, in full_dispatch_request
    rv = self.dispatch_request()
  File "/home/ubuntu/.local/lib/python2.7/site-packages/flask/app.py", line 1799, in dispatch_request
    return self.view_functions[rule.endpoint](**req.view_args)
  File "/home/ubuntu/SeeFood-Server/index.py", line 32, in upload_file
    f = request.files['the_file']
  File "/home/ubuntu/.local/lib/python2.7/site-packages/werkzeug/local.py", line 347, in __getattr__
    return getattr(self._get_current_object(), name)
  File "/home/ubuntu/.local/lib/python2.7/site-packages/werkzeug/utils.py", line 73, in __get__
    value = self.func(obj)
  File "/home/ubuntu/.local/lib/python2.7/site-packages/werkzeug/wrappers.py", line 571, in files
    self._load_form_data()
  File "/home/ubuntu/.local/lib/python2.7/site-packages/flask/wrappers.py", line 168, in _load_form_data
    RequestBase._load_form_data(self)
  File "/home/ubuntu/.local/lib/python2.7/site-packages/werkzeug/wrappers.py", line 385, in _load_form_data
    mimetype, content_length, options)
  File "/home/ubuntu/.local/lib/python2.7/site-packages/werkzeug/formparser.py", line 205, in parse
    content_length, options)
  File "/home/ubuntu/.local/lib/python2.7/site-packages/werkzeug/formparser.py", line 110, in wrapper
    return f(self, stream, *args, **kwargs)
  File "/home/ubuntu/.local/lib/python2.7/site-packages/werkzeug/formparser.py", line 222, in _parse_multipart
    form, files = parser.parse(stream, boundary, content_length)
  File "/home/ubuntu/.local/lib/python2.7/site-packages/werkzeug/formparser.py", line 531, in parse
    return self.cls(form), self.cls(files)
  File "/home/ubuntu/.local/lib/python2.7/site-packages/werkzeug/datastructures.py", line 409, in __init__
    for key, value in mapping or ():
  File "/home/ubuntu/.local/lib/python2.7/site-packages/werkzeug/formparser.py", line 529, in <genexpr>
    form = (p[1] for p in formstream if p[0] == 'form')
  File "/home/ubuntu/.local/lib/python2.7/site-packages/werkzeug/formparser.py", line 505, in parse_parts
    _write(ell)
  File "/opt/anaconda2/lib/python2.7/tempfile.py", line 626, in write
    rv = file.write(s)
IOError: [Errno 28] No space left on device
[2018-12-03 16:14:10,086] ERROR in app: Exception on /upload [GET]
Traceback (most recent call last):
  File "/home/ubuntu/.local/lib/python2.7/site-packages/flask/app.py", line 2292, in wsgi_app
    response = self.full_dispatch_request()
  File "/home/ubuntu/.local/lib/python2.7/site-packages/flask/app.py", line 1815, in full_dispatch_request
    rv = self.handle_user_exception(e)
  File "/home/ubuntu/.local/lib/python2.7/site-packages/flask/app.py", line 1718, in handle_user_exception
    reraise(exc_type, exc_value, tb)
  File "/home/ubuntu/.local/lib/python2.7/site-packages/flask/app.py", line 1813, in full_dispatch_request
    rv = self.dispatch_request()
  File "/home/ubuntu/.local/lib/python2.7/site-packages/flask/app.py", line 1799, in dispatch_request
    return self.view_functions[rule.endpoint](**req.view_args)
  File "/home/ubuntu/SeeFood-Server/index.py", line 45, in upload_file
    return filesFromDB()
  File "/home/ubuntu/SeeFood-Server/index.py", line 226, in filesFromDB
    db = MySQLdb.connect("127.0.0.1", "root", "", "SeeFood")
  File "/home/ubuntu/.local/lib/python2.7/site-packages/MySQLdb/__init__.py", line 81, in Connect
    return Connection(*args, **kwargs)
  File "/home/ubuntu/.local/lib/python2.7/site-packages/MySQLdb/connections.py", line 193, in __init__
    super(Connection, self).__init__(*args, **kwargs2)
OperationalError: (1049, "Unknown database 'SeeFood'")
[2018-12-03 16:14:14,170] ERROR in app: Exception on /upload [GET]
Traceback (most recent call last):
  File "/home/ubuntu/.local/lib/python2.7/site-packages/flask/app.py", line 2292, in wsgi_app
    response = self.full_dispatch_request()
  File "/home/ubuntu/.local/lib/python2.7/site-packages/flask/app.py", line 1815, in full_dispatch_request
    rv = self.handle_user_exception(e)
  File "/home/ubuntu/.local/lib/python2.7/site-packages/flask/app.py", line 1718, in handle_user_exception
    reraise(exc_type, exc_value, tb)
  File "/home/ubuntu/.local/lib/python2.7/site-packages/flask/app.py", line 1813, in full_dispatch_request
    rv = self.dispatch_request()
  File "/home/ubuntu/.local/lib/python2.7/site-packages/flask/app.py", line 1799, in dispatch_request
    return self.view_functions[rule.endpoint](**req.view_args)
  File "/home/ubuntu/SeeFood-Server/index.py", line 45, in upload_file
    return filesFromDB()
  File "/home/ubuntu/SeeFood-Server/index.py", line 226, in filesFromDB
    db = MySQLdb.connect("127.0.0.1", "root", "", "SeeFood")
  File "/home/ubuntu/.local/lib/python2.7/site-packages/MySQLdb/__init__.py", line 81, in Connect
    return Connection(*args, **kwargs)
  File "/home/ubuntu/.local/lib/python2.7/site-packages/MySQLdb/connections.py", line 193, in __init__
    super(Connection, self).__init__(*args, **kwargs2)
OperationalError: (1049, "Unknown database 'SeeFood'")
[2018-12-03 16:14:14,418] ERROR in app: Exception on /upload [GET]
Traceback (most recent call last):
  File "/home/ubuntu/.local/lib/python2.7/site-packages/flask/app.py", line 2292, in wsgi_app
    response = self.full_dispatch_request()
  File "/home/ubuntu/.local/lib/python2.7/site-packages/flask/app.py", line 1815, in full_dispatch_request
    rv = self.handle_user_exception(e)
  File "/home/ubuntu/.local/lib/python2.7/site-packages/flask/app.py", line 1718, in handle_user_exception
    reraise(exc_type, exc_value, tb)
  File "/home/ubuntu/.local/lib/python2.7/site-packages/flask/app.py", line 1813, in full_dispatch_request
    rv = self.dispatch_request()
  File "/home/ubuntu/.local/lib/python2.7/site-packages/flask/app.py", line 1799, in dispatch_request
    return self.view_functions[rule.endpoint](**req.view_args)
  File "/home/ubuntu/SeeFood-Server/index.py", line 45, in upload_file
    return filesFromDB()
  File "/home/ubuntu/SeeFood-Server/index.py", line 226, in filesFromDB
    db = MySQLdb.connect("127.0.0.1", "root", "", "SeeFood")
  File "/home/ubuntu/.local/lib/python2.7/site-packages/MySQLdb/__init__.py", line 81, in Connect
    return Connection(*args, **kwargs)
  File "/home/ubuntu/.local/lib/python2.7/site-packages/MySQLdb/connections.py", line 193, in __init__
    super(Connection, self).__init__(*args, **kwargs2)
OperationalError: (1049, "Unknown database 'SeeFood'")
[2018-12-03 16:14:15,272] ERROR in app: Exception on /upload [GET]
Traceback (most recent call last):
  File "/home/ubuntu/.local/lib/python2.7/site-packages/flask/app.py", line 2292, in wsgi_app
    response = self.full_dispatch_request()
  File "/home/ubuntu/.local/lib/python2.7/site-packages/flask/app.py", line 1815, in full_dispatch_request
    rv = self.handle_user_exception(e)
  File "/home/ubuntu/.local/lib/python2.7/site-packages/flask/app.py", line 1718, in handle_user_exception
    reraise(exc_type, exc_value, tb)
  File "/home/ubuntu/.local/lib/python2.7/site-packages/flask/app.py", line 1813, in full_dispatch_request
    rv = self.dispatch_request()
  File "/home/ubuntu/.local/lib/python2.7/site-packages/flask/app.py", line 1799, in dispatch_request
    return self.view_functions[rule.endpoint](**req.view_args)
  File "/home/ubuntu/SeeFood-Server/index.py", line 45, in upload_file
    return filesFromDB()
  File "/home/ubuntu/SeeFood-Server/index.py", line 226, in filesFromDB
    db = MySQLdb.connect("127.0.0.1", "root", "", "SeeFood")
  File "/home/ubuntu/.local/lib/python2.7/site-packages/MySQLdb/__init__.py", line 81, in Connect
    return Connection(*args, **kwargs)
  File "/home/ubuntu/.local/lib/python2.7/site-packages/MySQLdb/connections.py", line 193, in __init__
    super(Connection, self).__init__(*args, **kwargs2)
OperationalError: (1049, "Unknown database 'SeeFood'")
[2018-12-03 16:14:33,715] ERROR in app: Exception on /upload [GET]
Traceback (most recent call last):
  File "/home/ubuntu/.local/lib/python2.7/site-packages/flask/app.py", line 2292, in wsgi_app
    response = self.full_dispatch_request()
  File "/home/ubuntu/.local/lib/python2.7/site-packages/flask/app.py", line 1815, in full_dispatch_request
    rv = self.handle_user_exception(e)
  File "/home/ubuntu/.local/lib/python2.7/site-packages/flask/app.py", line 1718, in handle_user_exception
    reraise(exc_type, exc_value, tb)
  File "/home/ubuntu/.local/lib/python2.7/site-packages/flask/app.py", line 1813, in full_dispatch_request
    rv = self.dispatch_request()
  File "/home/ubuntu/.local/lib/python2.7/site-packages/flask/app.py", line 1799, in dispatch_request
    return self.view_functions[rule.endpoint](**req.view_args)
  File "/home/ubuntu/SeeFood-Server/index.py", line 45, in upload_file
    return filesFromDB()
  File "/home/ubuntu/SeeFood-Server/index.py", line 226, in filesFromDB
    db = MySQLdb.connect("127.0.0.1", "root", "", "SeeFood")
  File "/home/ubuntu/.local/lib/python2.7/site-packages/MySQLdb/__init__.py", line 81, in Connect
    return Connection(*args, **kwargs)
  File "/home/ubuntu/.local/lib/python2.7/site-packages/MySQLdb/connections.py", line 193, in __init__
    super(Connection, self).__init__(*args, **kwargs2)
OperationalError: (1049, "Unknown database 'SeeFood'")
[2018-12-03 16:15:14,176] ERROR in app: Exception on /upload [POST]
Traceback (most recent call last):
  File "/home/ubuntu/.local/lib/python2.7/site-packages/flask/app.py", line 2292, in wsgi_app
    response = self.full_dispatch_request()
  File "/home/ubuntu/.local/lib/python2.7/site-packages/flask/app.py", line 1815, in full_dispatch_request
    rv = self.handle_user_exception(e)
  File "/home/ubuntu/.local/lib/python2.7/site-packages/flask/app.py", line 1718, in handle_user_exception
    reraise(exc_type, exc_value, tb)
  File "/home/ubuntu/.local/lib/python2.7/site-packages/flask/app.py", line 1813, in full_dispatch_request
    rv = self.dispatch_request()
  File "/home/ubuntu/.local/lib/python2.7/site-packages/flask/app.py", line 1799, in dispatch_request
    return self.view_functions[rule.endpoint](**req.view_args)
  File "/home/ubuntu/SeeFood-Server/index.py", line 34, in upload_file
    results = fileToDB(f)
  File "/home/ubuntu/SeeFood-Server/index.py", line 57, in fileToDB
    db = MySQLdb.connect("127.0.0.1", "root", "", "SeeFood")
  File "/home/ubuntu/.local/lib/python2.7/site-packages/MySQLdb/__init__.py", line 81, in Connect
    return Connection(*args, **kwargs)
  File "/home/ubuntu/.local/lib/python2.7/site-packages/MySQLdb/connections.py", line 193, in __init__
    super(Connection, self).__init__(*args, **kwargs2)
OperationalError: (1049, "Unknown database 'SeeFood'")
[2018-12-03 16:36:03 +0000] [18562] [INFO] Handling signal: term
[2018-12-03 16:36:03 +0000] [18566] [INFO] Worker exiting (pid: 18566)
4AW.jpg
looking for food in files/72FQEYL.jpg
looking for food in files/72FQEYL.jpg
looking for food in files/7NJMG7X.jpg
looking for food in files/7NJMG7X.jpg
looking for food in files/10EFHJ6.jpg
looking for food in files/10EFHJ6.jpg
looking for food in files/BKKDU6B.jpg
looking for food in files/BKKDU6B.jpg
looking for food in files/0ZQ8HQL.jpg
looking for food in files/0ZQ8HQL.jpg
looking for food in files/56J2JW6.jpg
looking for food in files/56J2JW6.jpg
looking for food in files/IYUPHGF.jpg
looking for food in files/IYUPHGF.jpg
looking for food in files/5SJL2IW.jpg
looking for food in files/5SJL2IW.jpg
looking for food in files/3TEA549.jpg
looking for food in files/3TEA549.jpg
looking for food in files/KQUGWM6.jpg
looking for food in files/KQUGWM6.jpg
looking for food in files/WGQC2HI.jpg
looking for food in files/WGQC2HI.jpg
looking for food in files/SJW90M4.jpg
looking for food in files/SJW90M4.jpg
looking for food in files/ZUPI6FM.jpg
looking for food in files/ZUPI6FM.jpg
looking for food in files/CZRYJKY.jpg
looking for food in files/CZRYJKY.jpg
looking for food in files/XMJ7KDS.jpg
looking for food in files/XMJ7KDS.jpg
looking for food in files/51RL836.jpg
looking for food in files/51RL836.jpg
looking for food in files/551WA6Y.jpg
looking for food in files/551WA6Y.jpg
looking for food in files/DZZZ1H4.jpg
looking for food in files/DZZZ1H4.jpg
looking for food in files/7Z2J4Y7.jpg
looking for food in files/7Z2J4Y7.jpg
[2018-12-03 16:36:04 +0000] [18562] [INFO] Shutting down: Master
[2018-12-03 16:36:06 +0000] [2649] [INFO] Starting gunicorn 19.9.0
[2018-12-03 16:36:06 +0000] [2649] [INFO] Listening at: http://127.0.0.1:8000 (2649)
[2018-12-03 16:36:06 +0000] [2649] [INFO] Using worker: sync
[2018-12-03 16:36:06 +0000] [2653] [INFO] Booting worker with pid: 2653
/opt/anaconda2/lib/python2.7/site-packages/h5py/__init__.py:36: FutureWarning: Conversion of the second argument of issubdtype from `float` to `np.floating` is deprecated. In future, it will be treated as `np.float64 == np.dtype(float).type`.
  from ._conv import register_converters as _register_converters
2018-12-03 16:36:08.484646: I tensorflow/core/platform/cpu_feature_guard.cc:141] Your CPU supports instructions that this TensorFlow binary was not compiled to use: SSE4.1 SSE4.2 AVX AVX2 FMA
2018-12-03 16:36:08.488557: I tensorflow/core/common_runtime/process_util.cc:69] Creating new thread pool with default inter op setting: 2. Tune using inter_op_parallelism_threads for best performance.
[2018-12-03 16:46:34,808] ERROR in app: Exception on /upload [POST]
Traceback (most recent call last):
  File "/home/ubuntu/.local/lib/python2.7/site-packages/flask/app.py", line 2292, in wsgi_app
    response = self.full_dispatch_request()
  File "/home/ubuntu/.local/lib/python2.7/site-packages/flask/app.py", line 1815, in full_dispatch_request
    rv = self.handle_user_exception(e)
  File "/home/ubuntu/.local/lib/python2.7/site-packages/flask/app.py", line 1718, in handle_user_exception
    reraise(exc_type, exc_value, tb)
  File "/home/ubuntu/.local/lib/python2.7/site-packages/flask/app.py", line 1813, in full_dispatch_request
    rv = self.dispatch_request()
  File "/home/ubuntu/.local/lib/python2.7/site-packages/flask/app.py", line 1799, in dispatch_request
    return self.view_functions[rule.endpoint](**req.view_args)
  File "/home/ubuntu/SeeFood-Server/index.py", line 32, in upload_file
    f = request.files['the_file']
  File "/home/ubuntu/.local/lib/python2.7/site-packages/werkzeug/local.py", line 347, in __getattr__
    return getattr(self._get_current_object(), name)
  File "/home/ubuntu/.local/lib/python2.7/site-packages/werkzeug/utils.py", line 73, in __get__
    value = self.func(obj)
  File "/home/ubuntu/.local/lib/python2.7/site-packages/werkzeug/wrappers.py", line 571, in files
    self._load_form_data()
  File "/home/ubuntu/.local/lib/python2.7/site-packages/flask/wrappers.py", line 168, in _load_form_data
    RequestBase._load_form_data(self)
  File "/home/ubuntu/.local/lib/python2.7/site-packages/werkzeug/wrappers.py", line 385, in _load_form_data
    mimetype, content_length, options)
  File "/home/ubuntu/.local/lib/python2.7/site-packages/werkzeug/formparser.py", line 205, in parse
    content_length, options)
  File "/home/ubuntu/.local/lib/python2.7/site-packages/werkzeug/formparser.py", line 110, in wrapper
    return f(self, stream, *args, **kwargs)
  File "/home/ubuntu/.local/lib/python2.7/site-packages/werkzeug/formparser.py", line 222, in _parse_multipart
    form, files = parser.parse(stream, boundary, content_length)
  File "/home/ubuntu/.local/lib/python2.7/site-packages/werkzeug/formparser.py", line 531, in parse
    return self.cls(form), self.cls(files)
  File "/home/ubuntu/.local/lib/python2.7/site-packages/werkzeug/datastructures.py", line 409, in __init__
    for key, value in mapping or ():
  File "/home/ubuntu/.local/lib/python2.7/site-packages/werkzeug/formparser.py", line 529, in <genexpr>
    form = (p[1] for p in formstream if p[0] == 'form')
  File "/home/ubuntu/.local/lib/python2.7/site-packages/werkzeug/formparser.py", line 505, in parse_parts
    _write(ell)
  File "/opt/anaconda2/lib/python2.7/tempfile.py", line 626, in write
    rv = file.write(s)
IOError: [Errno 28] No space left on device
[2018-12-03 16:58:54 +0000] [2649] [INFO] Handling signal: term
[2018-12-03 16:58:54 +0000] [2653] [INFO] Worker exiting (pid: 2653)
looking for food in files/M2M6RKB.jpg
looking for food in files/M2M6RKB.jpg
looking for food in files/Q2CFSG8.jpg
looking for food in files/Q2CFSG8.jpg
looking for food in files/6NOITEZ.jpg
looking for food in files/6NOITEZ.jpg
[2018-12-03 16:58:54 +0000] [2649] [INFO] Shutting down: Master
[2018-12-03 16:58:56 +0000] [2921] [INFO] Starting gunicorn 19.9.0
[2018-12-03 16:58:56 +0000] [2921] [INFO] Listening at: http://127.0.0.1:8000 (2921)
[2018-12-03 16:58:56 +0000] [2921] [INFO] Using worker: sync
[2018-12-03 16:58:56 +0000] [2925] [INFO] Booting worker with pid: 2925
/opt/anaconda2/lib/python2.7/site-packages/h5py/__init__.py:36: FutureWarning: Conversion of the second argument of issubdtype from `float` to `np.floating` is deprecated. In future, it will be treated as `np.float64 == np.dtype(float).type`.
  from ._conv import register_converters as _register_converters
2018-12-03 16:58:58.563821: I tensorflow/core/platform/cpu_feature_guard.cc:141] Your CPU supports instructions that this TensorFlow binary was not compiled to use: SSE4.1 SSE4.2 AVX AVX2 FMA
2018-12-03 16:58:58.565296: I tensorflow/core/common_runtime/process_util.cc:69] Creating new thread pool with default inter op setting: 2. Tune using inter_op_parallelism_threads for best performance.
[2018-12-03 17:02:31 +0000] [2921] [INFO] Handling signal: term
[2018-12-03 17:02:31 +0000] [2925] [INFO] Worker exiting (pid: 2925)
[Errno 28] No space left on device
[2018-12-03 17:02:32 +0000] [2921] [INFO] Shutting down: Master
[2018-12-03 17:02:33 +0000] [3087] [INFO] Starting gunicorn 19.9.0
[2018-12-03 17:02:33 +0000] [3087] [INFO] Listening at: http://127.0.0.1:8000 (3087)
[2018-12-03 17:02:33 +0000] [3087] [INFO] Using worker: sync
[2018-12-03 17:02:33 +0000] [3091] [INFO] Booting worker with pid: 3091
/opt/anaconda2/lib/python2.7/site-packages/h5py/__init__.py:36: FutureWarning: Conversion of the second argument of issubdtype from `float` to `np.floating` is deprecated. In future, it will be treated as `np.float64 == np.dtype(float).type`.
  from ._conv import register_converters as _register_converters
2018-12-03 17:02:35.897072: I tensorflow/core/platform/cpu_feature_guard.cc:141] Your CPU supports instructions that this TensorFlow binary was not compiled to use: SSE4.1 SSE4.2 AVX AVX2 FMA
2018-12-03 17:02:35.897893: I tensorflow/core/common_runtime/process_util.cc:69] Creating new thread pool with default inter op setting: 2. Tune using inter_op_parallelism_threads for best performance.
[2018-12-03 20:18:16,957] ERROR in app: Exception on /upload [POST]
Traceback (most recent call last):
  File "/home/ubuntu/.local/lib/python2.7/site-packages/flask/app.py", line 2292, in wsgi_app
    response = self.full_dispatch_request()
  File "/home/ubuntu/.local/lib/python2.7/site-packages/flask/app.py", line 1815, in full_dispatch_request
    rv = self.handle_user_exception(e)
  File "/home/ubuntu/.local/lib/python2.7/site-packages/flask/app.py", line 1718, in handle_user_exception
    reraise(exc_type, exc_value, tb)
  File "/home/ubuntu/.local/lib/python2.7/site-packages/flask/app.py", line 1813, in full_dispatch_request
    rv = self.dispatch_request()
  File "/home/ubuntu/.local/lib/python2.7/site-packages/flask/app.py", line 1799, in dispatch_request
    return self.view_functions[rule.endpoint](**req.view_args)
  File "/home/ubuntu/SeeFood-Server/index.py", line 32, in upload_file
    f = request.files['the_file']
  File "/home/ubuntu/.local/lib/python2.7/site-packages/werkzeug/local.py", line 347, in __getattr__
    return getattr(self._get_current_object(), name)
  File "/home/ubuntu/.local/lib/python2.7/site-packages/werkzeug/utils.py", line 73, in __get__
    value = self.func(obj)
  File "/home/ubuntu/.local/lib/python2.7/site-packages/werkzeug/wrappers.py", line 571, in files
    self._load_form_data()
  File "/home/ubuntu/.local/lib/python2.7/site-packages/flask/wrappers.py", line 168, in _load_form_data
    RequestBase._load_form_data(self)
  File "/home/ubuntu/.local/lib/python2.7/site-packages/werkzeug/wrappers.py", line 385, in _load_form_data
    mimetype, content_length, options)
  File "/home/ubuntu/.local/lib/python2.7/site-packages/werkzeug/formparser.py", line 205, in parse
    content_length, options)
  File "/home/ubuntu/.local/lib/python2.7/site-packages/werkzeug/formparser.py", line 110, in wrapper
    return f(self, stream, *args, **kwargs)
  File "/home/ubuntu/.local/lib/python2.7/site-packages/werkzeug/formparser.py", line 222, in _parse_multipart
    form, files = parser.parse(stream, boundary, content_length)
  File "/home/ubuntu/.local/lib/python2.7/site-packages/werkzeug/formparser.py", line 531, in parse
    return self.cls(form), self.cls(fi
[2018-12-03 20:31:30,109] ERROR in app: Exception on /upload [POST]
Traceback (most recent call last):
  File "/home/ubuntu/.local/lib/python2.7/site-packages/flask/app.py", line 2292, in wsgi_app
    response = self.full_dispatch_request()
  File "/home/ubuntu/.local/lib/python2.7/site-packages/flask/app.py", line 1815, in full_dispatch_request
    rv = self.handle_user_exception(e)
  File "/home/ubuntu/.local/lib/python2.7/site-packages/flask/app.py", line 1718, in handle_user_exception
    reraise(exc_type, exc_value, tb)
  File "/home/ubuntu/.local/lib/python2.7/site-packages/flask/app.py", line 1813, in full_dispatch_request
    rv = self.dispatch_request()
  File "/home/ubuntu/.local/lib/python2.7/site-packages/flask/app.py", line 1799, in dispatch_request
    return self.view_functions[rule.endpoint](**req.view_args)
  File "/home/ubuntu/SeeFood-Server/index.py", line 32, in upload_file
    f = request.files['the_file']
  File "/home/ubuntu/.local/lib/python2.7/site-packages/werkzeug/local.py", line 347, in __getattr__
    return getattr(self._get_current_object(), name)
  File "/home/ubuntu/.local/lib/python2.7/site-packages/werkzeug/utils.py", line 73, in __get__
    value = self.func(obj)
  File "/home/ubuntu/.local/lib/python2.7/site-packages/werkzeug/wrappers.py", line 571, in files
    self._load_form_data()
  File "/home/ubuntu/.local/lib/python2.7/site-packages/flask/wrappers.py", line 168, in _load_form_data
    RequestBase._load_form_data(self)
  File "/home/ubuntu/.local/lib/python2.7/site-packages/werkzeug/wrappers.py", line 385, in _load_form_data
    mimetype, content_length, options)
  File "/home/ubuntu/.local/lib/python2.7/site-packages/werkzeug/formparser.py", line 205, in parse
    content_length, options)
  File "/home/ubuntu/.local/lib/python2.7/site-packages/werkzeug/formparser.py", line 110, in wrapper
    return f(self, stream, *args, **kwargs)
  File "/home/ubuntu/.local/lib/python2.7/site-packages/werkzeug/formparser.py", line 222, in _parse_multipart
    form, files = parser.parse(stream, boundary, content_length)
  File "/home/ubuntu/.local/lib/python2.7/site-packages/werkzeug/formparser.py", line 531, in parse
    return self.cls(form), self.cls(files)
  File "/home/ubuntu/.local/lib/python2.7/site-packages/werkzeug/datastructures.py", line 409, in __init__
    for key, value in mapping or ():
  File "/home/ubuntu/.local/lib/python2.7/site-packages/werkzeug/formparser.py", line 529, in <genexpr>
    form = (p[1] for p in formstream if p[0] == 'form')
  File "/home/ubuntu/.local/lib/python2.7/site-packages/werkzeug/formparser.py", line 505, in parse_parts
    _write(ell)
  File "/opt/anaconda2/lib/python2.7/tempfile.py", line 626, in write
    rv = file.write(s)
IOError: [Errno 28] No space left on device
[2018-12-03 20:34:00 +0000] [3087] [INFO] Handling signal: term
[2018-12-03 20:34:00 +0000] [3091] [INFO] Worker exiting (pid: 3091)
looking for food in files/1PTM3YI.jpg
looking for food in files/1PTM3YI.jpg
looking for food in files/KEHSSJY.jpg
looking for food in files/KEHSSJY.jpg
[Errno 28] No space left on device
looking for food in files/ZKSU9KZ.jpg
looking for food in files/ZKSU9KZ.jpg
looking for food in files/Z6CPL84.jpg
looking for food in files/Z6CPL84.jpg
[2018-12-03 20:34:00 +0000] [3087] [INFO] Shutting down: Master
[2018-12-03 20:34:02 +0000] [3926] [INFO] Starting gunicorn 19.9.0
[2018-12-03 20:34:02 +0000] [3926] [INFO] Listening at: http://127.0.0.1:8000 (3926)
[2018-12-03 20:34:02 +0000] [3926] [INFO] Using worker: sync
[2018-12-03 20:34:02 +0000] [3930] [INFO] Booting worker with pid: 3930
/opt/anaconda2/lib/python2.7/site-packages/h5py/__init__.py:36: FutureWarning: Conversion of the second argument of issubdtype from `float` to `np.floating` is deprecated. In future, it will be treated as `np.float64 == np.dtype(float).type`.
  from ._conv import register_converters as _register_converters
2018-12-03 20:34:05.409091: I tensorflow/core/platform/cpu_feature_guard.cc:141] Your CPU supports instructions that this TensorFlow binary was not compiled to use: SSE4.1 SSE4.2 AVX AVX2 FMA
2018-12-03 20:34:05.409956: I tensorflow/core/common_runtime/process_util.cc:69] Creating new thread pool with default inter op setting: 2. Tune using inter_op_parallelism_threads for best performance.
[2018-12-03 20:34:19,556] ERROR in app: Exception on /upload [POST]
Traceback (most recent call last):
  File "/home/ubuntu/.local/lib/python2.7/site-packages/flask/app.py", line 2292, in wsgi_app
    response = self.full_dispatch_request()
  File "/home/ubuntu/.local/lib/python2.7/site-packages/flask/app.py", line 1815, in full_dispatch_request
    rv = self.handle_user_exception(e)
  File "/home/ubuntu/.local/lib/python2.7/site-packages/flask/app.py", line 1718, in handle_user_exception
    reraise(exc_type, exc_value, tb)
  File "/home/ubuntu/.local/lib/python2.7/site-packages/flask/app.py", line 1813, in full_dispatch_request
    rv = self.dispatch_request()
  File "/home/ubuntu/.local/lib/python2.7/site-packages/flask/app.py", line 1799, in dispatch_request
    return self.view_functions[rule.endpoint](**req.view_args)
  File "/home/ubuntu/SeeFood-Server/index.py", line 32, in upload_file
    f = request.files['the_file']
  File "/home/ubuntu/.local/lib/python2.7/site-packages/werkzeug/local.py", line 347, in __getattr__
    return getattr(self._get_current_object(), name)
  File "/home/ubuntu/.local/lib/python2.7/site-packages/werkzeug/utils.py", line 73, in __get__
    value = self.func(obj)
  File "/home/ubuntu/.local/lib/python2.7/site-packages/werkzeug/wrappers.py", line 571, in files
    self._load_form_data()
  File "/home/ubuntu/.local/lib/python2.7/site-packages/flask/wrappers.py", line 168, in _load_form_data
    RequestBase._load_form_data(self)
  File "/home/ubuntu/.local/lib/python2.7/site-packages/werkzeug/wrappers.py", line 385, in _load_form_data
    mimetype, content_length, options)
  File "/home/ubuntu/.local/lib/python2.7/site-packages/werkzeug/formparser.py", line 205, in parse
    content_length, options)
  File "/home/ubuntu/.local/lib/python2.7/site-packages/werkzeug/formparser.py", line 110, in wrapper
    return f(self, stream, *args, **kwargs)
  File "/home/ubuntu/.local/lib/python2.7/site-packages/werkzeug/formparser.py", line 222, in _parse_multipart
    form, files = parser.parse(stream, boundary, content_length)
  File "/home/ubuntu/.local/lib/python2.7/site-packages/werkzeug/formparser.py", line 531, in parse
    return self.cls(form), self.cls(files)
  File "/home/ubuntu/.local/lib/python2.7/site-packages/werkzeug/datastructures.py", line 409, in __init__
    for key, value in mapping or ():
  File "/home/ubuntu/.local/lib/python2.7/site-packages/werkzeug/formparser.py", line 529, in <genexpr>
    form = (p[1] for p in formstream if p[0] == 'form')
  File "/home/ubuntu/.local/lib/python2.7/site-packages/werkzeug/formparser.py", line 505, in parse_parts
    _write(ell)
  File "/opt/anaconda2/lib/python2.7/tempfile.py", line 626, in write
    rv = file.write(s)
IOError: [Errno 28] No spac[2018-12-03 20:36:18 +0000] [3926] [INFO] Handling signal: term
[2018-12-03 20:36:18 +0000] [3930] [INFO] Worker exiting (pid: 3930)
[2018-12-03 20:36:18 +0000] [3926] [INFO] Shutting down: Master
[2018-12-03 20:36:19 +0000] [4197] [INFO] Starting gunicorn 19.9.0
[2018-12-03 20:36:19 +0000] [4197] [INFO] Listening at: http://127.0.0.1:8000 (4197)
[2018-12-03 20:36:19 +0000] [4197] [INFO] Using worker: sync
[2018-12-03 20:36:19 +0000] [4201] [INFO] Booting worker with pid: 4201
/opt/anaconda2/lib/python2.7/site-packages/h5py/__init__.py:36: FutureWarning: Conversion of the second argument of issubdtype from `float` to `np.floating` is deprecated. In future, it will be treated as `np.float64 == np.dtype(float).type`.
  from ._conv import register_converters as _register_converters
2018-12-03 20:36:22.127177: I tensorflow/core/platform/cpu_feature_guard.cc:141] Your CPU supports instructions that this TensorFlow binary was not compiled to use: SSE4.1 SSE4.2 AVX AVX2 FMA
2018-12-03 20:36:22.128030: I tensorflow/core/common_runtime/process_util.cc:69] Creating new thread pool with default inter op setting: 2. Tune using inter_op_parallelism_threads for best performance.
[2018-12-03 20:46:44 +0000] [4197] [INFO] Handling signal: term
[2018-12-03 20:46:44 +0000] [4201] [INFO] Worker exiting (pid: 4201)
looking for food in files/HKXDB3T.jpg
looking for food in files/HKXDB3T.jpg
[2018-12-03 20:46:45 +0000] [4197] [INFO] Shutting down: Master
[2018-12-03 20:46:46 +0000] [4350] [INFO] Starting gunicorn 19.9.0
[2018-12-03 20:46:46 +0000] [4350] [INFO] Listening at: http://127.0.0.1:8000 (4350)
[2018-12-03 20:46:46 +0000] [4350] [INFO] Using worker: sync
[2018-12-03 20:46:46 +0000] [4354] [INFO] Booting worker with pid: 4354
/opt/anaconda2/lib/python2.7/site-packages/h5py/__init__.py:36: FutureWarning: Conversion of the second argument of issubdtype from `float` to `np.floating` is deprecated. In future, it will be treated as `np.float64 == np.dtype(float).type`.
  from ._conv import register_converters as _register_converters
2018-12-03 20:46:48.459072: I tensorflow/core/platform/cpu_feature_guard.cc:141] Your CPU supports instructions that this TensorFlow binary was not compiled to use: SSE4.1 SSE4.2 AVX AVX2 FMA
2018-12-03 20:46:48.459918: I tensorflow/core/common_runtime/process_util.cc:69] Creating new thread pool with default inter op setting: 2. Tune using inter_op_parallelism_threads for best performance.
[2018-12-03 20:49:08,601] ERROR in app: Exception on /upload [POST]
Traceback (most recent call last):
  File "/home/ubuntu/.local/lib/python2.7/site-packages/flask/app.py", line 2292, in wsgi_app
    response = self.full_dispatch_request()
  File "/home/ubuntu/.local/lib/python2.7/site-packages/flask/app.py", line 1815, in full_dispatch_request
    rv = self.handle_user_exception(e)
  File "/home/ubuntu/.local/lib/python2.7/site-packages/flask/app.py", line 1718, in handle_user_exception
    reraise(exc_type, exc_value, tb)
  File "/home/ubuntu/.local/lib/python2.7/site-packages/flask/app.py", line 1813, in full_dispatch_request
    rv = self.dispatch_request()
  File "/home/ubuntu/.local/lib/python2.7/site-packages/flask/app.py", line 1799, in dispatch_request
    return self.view_functions[rule.endpoint](**req.view_args)
  File "/home/ubuntu/SeeFood-Server/index.py", line 34, in upload_file
    results = fileToDB(f)
  File "/home/ubuntu/SeeFood-Server/index.py", line 57, in fileToDB
    db = MySQLdb.connect("127.0.0.1", "root", "", "SeeFood")
  File "/home/ubuntu/.local/lib/python2.7/site-packages/MySQLdb/__init__.py", line 81, in Connect
    return Connection(*args, **kwargs)
  File "/home/ubuntu/.local/lib/python2.7/site-packages/MySQLdb/connections.py", line 193, in __init__
    super(Connection, self).__init__(*args, **kwargs2)
OperationalError: (1049, "Unknown database 'SeeFood'")
[2018-12-03 20:49:34 +0000] [4350] [INFO] Handling signal: term
[2018-12-03 20:49:34 +0000] [4354] [INFO] Worker exiting (pid: 4354)
[Errno 28] No space left on device
global name 'Image' is not defined
[2018-12-03 20:49:35 +0000] [4350] [INFO] Shutting down: Master
[2018-12-03 20:58:55 +0000] [1451] [INFO] Starting gunicorn 19.9.0
[2018-12-03 20:58:55 +0000] [1451] [INFO] Listening at: http://127.0.0.1:8000 (1451)
[2018-12-03 20:58:55 +0000] [1451] [INFO] Using worker: sync
[2018-12-03 20:58:55 +0000] [1478] [INFO] Booting worker with pid: 1478
/opt/anaconda2/lib/python2.7/site-packages/h5py/__init__.py:36: FutureWarning: Conversion of the second argument of issubdtype from `float` to `np.floating` is deprecated. In future, it will be treated as `np.float64 == np.dtype(float).type`.
  from ._conv import register_converters as _register_converters
2018-12-03 20:59:00.618559: I tensorflow/core/platform/cpu_feature_guard.cc:141] Your CPU supports instructions that this TensorFlow binary was not compiled to use: SSE4.1 SSE4.2 AVX AVX2 AVX512F FMA
2018-12-03 20:59:00.627135: I tensorflow/core/common_runtime/process_util.cc:69] Creating new thread pool with default inter op setting: 2. Tune using inter_op_parallelism_threads for best performance.
[2018-12-03 21:00:51 +0000] [1451] [INFO] Handling signal: term
[2018-12-03 21:00:51 +0000] [1478] [INFO] Worker exiting (pid: 1478)
[2018-12-03 21:00:51 +0000] [1451] [INFO] Shutting down: Master
[2018-12-03 21:00:53 +0000] [1658] [INFO] Starting gunicorn 19.9.0
[2018-12-03 21:00:53 +0000] [1658] [INFO] Listening at: http://127.0.0.1:8000 (1658)
[2018-12-03 21:00:53 +0000] [1658] [INFO] Using worker: sync
[2018-12-03 21:00:53 +0000] [1662] [INFO] Booting worker with pid: 1662
/opt/anaconda2/lib/python2.7/site-packages/h5py/__init__.py:36: FutureWarning: Conversion of the second argument of issubdtype from `float` to `np.floating` is deprecated. In future, it will be treated as `np.float64 == np.dtype(float).type`.
  from ._conv import register_converters as _register_converters
2018-12-03 21:00:54.202679: I tensorflow/core/platform/cpu_feature_guard.cc:141] Your CPU supports instructions that this TensorFlow binary was not compiled to use: SSE4.1 SSE4.2 AVX AVX2 AVX512F FMA
2018-12-03 21:00:54.203398: I tensorflow/core/common_runtime/process_util.cc:69] Creating new thread pool with default inter op setting: 2. Tune using inter_op_parallelism_threads for best performance.
[2018-12-03 21:01:39 +0000] [1658] [INFO] Handling signal: term
[2018-12-03 21:01:39 +0000] [1662] [INFO] Worker exiting (pid: 1662)
[2018-12-03 21:01:39 +0000] [1658] [INFO] Shutting down: Master
[2018-12-03 21:01:40 +0000] [1777] [INFO] Starting gunicorn 19.9.0
[2018-12-03 21:01:40 +0000] [1777] [INFO] Listening at: http://127.0.0.1:8000 (1777)
[2018-12-03 21:01:40 +0000] [1777] [INFO] Using worker: sync
[2018-12-03 21:01:40 +0000] [1781] [INFO] Booting worker with pid: 1781
/opt/anaconda2/lib/python2.7/site-packages/h5py/__init__.py:36: FutureWarning: Conversion of the second argument of issubdtype from `float` to `np.floating` is deprecated. In future, it will be treated as `np.float64 == np.dtype(float).type`.
  from ._conv import register_converters as _register_converters
2018-12-03 21:01:41.706782: I tensorflow/core/platform/cpu_feature_guard.cc:141] Your CPU supports instructions that this TensorFlow binary was not compiled to use: SSE4.1 SSE4.2 AVX AVX2 AVX512F FMA
2018-12-03 21:01:41.707566: I tensorflow/core/common_runtime/process_util.cc:69] Creating new thread pool with default inter op setting: 2. Tune using inter_op_parallelism_threads for best performance.
[2018-12-03 21:07:27 +0000] [1777] [INFO] Handling signal: term
[2018-12-03 21:07:27 +0000] [1781] [INFO] Worker exiting (pid: 1781)
looking for food in files/TP2ENKJ.jpg
looking for food in files/TP2ENKJ.jpg
[2018-12-03 21:07:27 +0000] [1777] [INFO] Shutting down: Master
[2018-12-03 21:07:29 +0000] [1945] [INFO] Starting gunicorn 19.9.0
[2018-12-03 21:07:29 +0000] [1945] [INFO] Listening at: http://127.0.0.1:8000 (1945)
[2018-12-03 21:07:29 +0000] [1945] [INFO] Using worker: sync
[2018-12-03 21:07:29 +0000] [1949] [INFO] Booting worker with pid: 1949
/opt/anaconda2/lib/python2.7/site-packages/h5py/__init__.py:36: FutureWarning: Conversion of the second argument of issubdtype from `float` to `np.floating` is deprecated. In future, it will be treated as `np.float64 == np.dtype(float).type`.
  from ._conv import register_converters as _register_converters
2018-12-03 21:07:29.948814: I tensorflow/core/platform/cpu_feature_guard.cc:141] Your CPU supports instructions that this TensorFlow binary was not compiled to use: SSE4.1 SSE4.2 AVX AVX2 AVX512F FMA
2018-12-03 21:07:29.949634: I tensorflow/core/common_runtime/process_util.cc:69] Creating new thread pool with default inter op setting: 2. Tune using inter_op_parallelism_threads for best performance.
[2018-12-03 21:09:30 +0000] [1945] [INFO] Handling signal: term
[2018-12-03 21:09:30 +0000] [1949] [INFO] Worker exiting (pid: 1949)
looking for food in files/MI9JYT5.jpg
looking for food in files/MI9JYT5.jpg
[2018-12-03 21:09:30 +0000] [1945] [INFO] Shutting down: Master
[2018-12-03 21:09:32 +0000] [2111] [INFO] Starting gunicorn 19.9.0
[2018-12-03 21:09:32 +0000] [2111] [INFO] Listening at: http://127.0.0.1:8000 (2111)
[2018-12-03 21:09:32 +0000] [2111] [INFO] Using worker: sync
[2018-12-03 21:09:32 +0000] [2115] [INFO] Booting worker with pid: 2115
/opt/anaconda2/lib/python2.7/site-packages/h5py/__init__.py:36: FutureWarning: Conversion of the second argument of issubdtype from `float` to `np.floating` is deprecated. In future, it will be treated as `np.float64 == np.dtype(float).type`.
  from ._conv import register_converters as _register_converters
2018-12-03 21:09:33.139169: I tensorflow/core/platform/cpu_feature_guard.cc:141] Your CPU supports instructions that this TensorFlow binary was not compiled to use: SSE4.1 SSE4.2 AVX AVX2 AVX512F FMA
2018-12-03 21:09:33.143133: I tensorflow/core/common_runtime/process_util.cc:69] Creating new thread pool with default inter op setting: 2. Tune using inter_op_parallelism_threads for best performance.
